<robot name="onshape">
<link name="part2">
    <visual>
        <origin xyz="-0.0055189212023849538308 -0.0053819040919259189884 0.0056341909945921767044" rpy="2.7343962984979360919e-07 -4.0084602304090903287e-13 1.4651404634102378437e-06" />
        <geometry>
        <mesh filename="./part2.stl"/>
        </geometry>
        <material name="part2_material">
        <color rgba="0.2313725490196078538 0.38039215686274507888 0.7058823529411765163 1.0"/>
        </material>
    </visual>
    <collision>
        <origin xyz="-0.0055189212023849538308 -0.0053819040919259189884 0.0056341909945921767044" rpy="2.7343962984979360919e-07 -4.0084602304090903287e-13 1.4651404634102378437e-06" />
        <geometry>
        <mesh filename="./part2_physic.stl"/>
        </geometry>
    </collision>
</link>

<link name="part1">
    <visual>
        <origin xyz="-0.0055189183905689949416 -0.0053819035586019445955 0.0056341905383137736232" rpy="0 -0 0" />
        <geometry>
        <mesh filename="./part1.stl"/>
        </geometry>
        <material name="part1_material">
        <color rgba="0.91764705882352937127 0.91764705882352937127 0.91764705882352937127 1.0"/>
        </material>
    </visual>
    <collision>
        <origin xyz="-0.0055189183905689949416 -0.0053819035586019445955 0.0056341905383137736232" rpy="0 -0 0" />
        <geometry>
        <mesh filename="./part1_physic.stl"/>
        </geometry>
    </collision>
</link>

<joint name="center_axis" type="revolute">
    <origin xyz="0 0 0" rpy="0 0 0"/>
    <parent link="part2"/>
    <child link="part1"/>
    <limit effort="30" velocity="1.0" lower="-0.4" upper="0.0" />
    <axis xyz="0 1 0"/>
</joint>
</robot>
