<robot name="onshape">
<link name="fb_palm_ref_mir_v5">
<visual>
<origin xyz="-0.003872314138682364168 -0.0071868913738217625464 -0.028909163027282983038" rpy="0 -0 0" />
<geometry>
<mesh filename="./wrist.stl"/>
</geometry>
<material name="wrist_material">
<color rgba="0.76862745098039220171 0.88627450980392152857 0.95294117647058818044 1.0"/>
</material>
</visual>
<collision>
<origin xyz="-0.003872314138682364168 -0.0071868913738217625464 -0.028909163027282983038" rpy="0 -0 0" />
<geometry>
<mesh filename="./wrist.stl"/>
</geometry>
</collision>
<visual>
<origin xyz="0.001066406426528377499 -0.0078468492029091889417 -0.021502863120379678979" rpy="-3.1415716311473289579 -0.088555241482479646331 0" />
<geometry>
<mesh filename="./palm.stl"/>
</geometry>
<material name="palm_material">
<color rgba="0.49803921568627451677 0.49803921568627451677 0.49803921568627451677 1.0"/>
</material>
</visual>
<collision>
<origin xyz="0.001066406426528377499 -0.0078468492029091889417 -0.021502863120379678979" rpy="-3.1415716311473289579 -0.088555241482479646331 0" />
<geometry>
<mesh filename="./palm.stl"/>
</geometry>
</collision>
<inertial>
<origin xyz="-0.0038105787339101984679 -0.0058483274685780213889 -0.019910745106455077919" rpy="0 0 0"/>
<mass value="0.0099179440012525446613" />
<inertia ixx="2.7342953765124291794e-07" ixy="-2.5766852703422248266e-09"  ixz="-7.76797436656968307e-09" iyy="3.467387707633750814e-07" iyz="-3.9076227236606035877e-08" izz="1.5344148801571052959e-07" />
</inertial>
</link>

<link name="idx-f1_v3">
<visual>
<origin xyz="1.4699462580549348123e-05 0.00097723995259920391765 -1.084202172485504434e-19" rpy="3.7930245966227260056e-18 -7.5322549308026134352e-17 1.5458638384718461634" />
<geometry>
<mesh filename="./index_1.stl"/>
</geometry>
<material name="index_1_material">
<color rgba="0.2313725490196078538 0.38039215686274507888 0.7058823529411765163 1.0"/>
</material>
</visual>
<collision>
<origin xyz="1.4699462580549348123e-05 0.00097723995259920391765 -1.084202172485504434e-19" rpy="3.7930245966227260056e-18 -7.5322549308026134352e-17 1.5458638384718461634" />
<geometry>
<mesh filename="./index_1.stl"/>
</geometry>
</collision>
<inertial>
<origin xyz="3.2112843083721671162e-05 0.0044842994521085578069 -4.7737139970499566233e-12" rpy="0 0 0"/>
<mass value="0.00094349406217372375986" />
<inertia ixx="6.5860738722373559062e-09" ixy="3.2790901544841979461e-10"  ixz="2.6331870605405864971e-26" iyy="2.2258360502709581268e-09" iyz="-2.2772269817168270336e-25" izz="7.3219808210304059779e-09" />
</inertial>
</link>

<link name="idx-f2-lg_v3">
<visual>
<origin xyz="0.00022233297791745924854 -0.0023719290216695364422 6.9322960369944727071e-06" rpy="5.1125602110007427365e-17 7.3954519088041169917e-17 -1.0572593838212323014" />
<geometry>
<mesh filename="./index_2.stl"/>
</geometry>
<material name="index_2_material">
<color rgba="0.98039215686274505668 0.71372549019607844922 0.0039215686274509803377 1.0"/>
</material>
</visual>
<collision>
<origin xyz="0.00022233297791745924854 -0.0023719290216695364422 6.9322960369944727071e-06" rpy="5.1125602110007427365e-17 7.3954519088041169917e-17 -1.0572593838212323014" />
<geometry>
<mesh filename="./index_2.stl"/>
</geometry>
</collision>
<inertial>
<origin xyz="-0.001046104817338249773 -0.004432125739992291702 6.5976409530707229688e-06" rpy="0 0 0"/>
<mass value="0.00052398424978570613299" />
<inertia ixx="4.2915366528124728295e-09" ixy="5.8217531578865538926e-11"  ixz="2.9039203123798735118e-13" iyy="6.2215271969257748341e-10" iyz="3.5195995450777468668e-13" izz="4.3113562724289062871e-09" />
</inertial>
</link>

<joint name="index_joint" type="revolute">
<origin xyz="-0.001540538927564456817 0.0086198297672773517564 2.710505431213761085e-19" rpy="2.8948218957230762414e-15 -1.0547304841327890295e-14 -2.6429263663145419194" />
<parent link="idx-f1_v3" />
<child link="idx-f2-lg_v3" />
<axis xyz="0 0 1"/>
<limit effort="1" velocity="20" lower="0.0" upper="2.0943951023931952626"/>
<joint_properties friction="0.0"/>
</joint>

<joint name="palm_index" type="revolute">
<origin xyz="0.0013274127561161835898 -0.0047523568131636858072 -0.011239498263663312214" rpy="1.4822410852929539526 -2.0940066997489776559e-05 1.5707981860101327687" />
<parent link="fb_palm_ref_mir_v5" />
<child link="idx-f1_v3" />
<axis xyz="0 0 1"/>
<limit effort="1" velocity="20" lower="0" upper="1.570796326794896558"/>
<joint_properties friction="0.0"/>
</joint>

<link name="idx-f1_v3_2">
<visual>
<origin xyz="1.4699462580549781804e-05 0.0009772399525992073871 4.336808689942017736e-19" rpy="3.8122062463432438003e-18 -6.8155182046868126432e-17 1.5458638384718461634" />
<geometry>
<mesh filename="./index_1.stl"/>
</geometry>
<material name="index_1_material">
<color rgba="0.2313725490196078538 0.38039215686274507888 0.7058823529411765163 1.0"/>
</material>
</visual>
<collision>
<origin xyz="1.4699462580549781804e-05 0.0009772399525992073871 4.336808689942017736e-19" rpy="3.8122062463432438003e-18 -6.8155182046868126432e-17 1.5458638384718461634" />
<geometry>
<mesh filename="./index_1.stl"/>
</geometry>
</collision>
<inertial>
<origin xyz="3.2112843083722111619e-05 0.0044842994521085612764 -4.7737134800792086948e-12" rpy="0 0 0"/>
<mass value="0.00094349406217372375986" />
<inertia ixx="6.5860738722373559062e-09" ixy="3.2790901544841979461e-10"  ixz="2.2678298720963275045e-26" iyy="2.2258360502709581268e-09" iyz="-2.1711588075651719382e-25" izz="7.3219808210304026692e-09" />
</inertial>
</link>

<link name="idx-f2-lg_v3_2">
<visual>
<origin xyz="0.00022233297791745838118 -0.0023719290216695364422 6.9322960369942558667e-06" rpy="5.4129569408464892274e-17 9.0292829778344770436e-17 -1.0572593838212323014" />
<geometry>
<mesh filename="./index_2.stl"/>
</geometry>
<material name="index_2_material">
<color rgba="0.98039215686274505668 0.71372549019607844922 0.0039215686274509803377 1.0"/>
</material>
</visual>
<collision>
<origin xyz="0.00022233297791745838118 -0.0023719290216695364422 6.9322960369942558667e-06" rpy="5.4129569408464892274e-17 9.0292829778344770436e-17 -1.0572593838212323014" />
<geometry>
<mesh filename="./index_2.stl"/>
</geometry>
</collision>
<inertial>
<origin xyz="-0.0010461048173382504235 -0.0044321257399922908346 6.5976409530704807174e-06" rpy="0 0 0"/>
<mass value="0.00052398424978570613299" />
<inertia ixx="4.2915366528124720024e-09" ixy="5.8217531578865125336e-11"  ixz="2.9039203123801108011e-13" iyy="6.2215271969257738001e-10" iyz="3.5195995450780240409e-13" izz="4.3113562724289079415e-09" />
</inertial>
</link>

<joint name="middle_joint" type="revolute">
<origin xyz="-0.001540538927564437735 0.0086198297672773569605 4.336808689942017736e-19" rpy="-1.0645765700679691443e-14 -4.5492251087631363691e-15 -2.6429263663145454721" />
<parent link="idx-f1_v3_2" />
<child link="idx-f2-lg_v3_2" />
<axis xyz="0 0 1"/>
<limit effort="1" velocity="20" lower="0.0" upper="2.0943951023931952626"/>
<joint_properties friction="0.0"/>
</joint>

<joint name="palm_middle" type="revolute">
<origin xyz="-0.0024254965095490297819 -0.003847063442716395186 -0.01157269041696425485" rpy="1.4822410852929528424 -2.0940066999008896269e-05 1.5707981860101365434" />
<parent link="fb_palm_ref_mir_v5" />
<child link="idx-f1_v3_2" />
<axis xyz="0 0 1"/>
<limit effort="1" velocity="20" lower="0" upper="1.570796326794896558"/>
<joint_properties friction="0.0"/>
</joint>

<link name="idx-f1_v3_3">
<visual>
<origin xyz="1.4699462580549348123e-05 0.00097723995259920565237 0" rpy="3.8122062463432438003e-18 -6.8155182046868126432e-17 1.5458638384718461634" />
<geometry>
<mesh filename="./index_1.stl"/>
</geometry>
<material name="index_1_material">
<color rgba="0.2313725490196078538 0.38039215686274507888 0.7058823529411765163 1.0"/>
</material>
</visual>
<collision>
<origin xyz="1.4699462580549348123e-05 0.00097723995259920565237 0" rpy="3.8122062463432438003e-18 -6.8155182046868126432e-17 1.5458638384718461634" />
<geometry>
<mesh filename="./index_1.stl"/>
</geometry>
</collision>
<inertial>
<origin xyz="3.2112843083721684715e-05 0.0044842994521085595416 -4.773713913760077689e-12" rpy="0 0 0"/>
<mass value="0.00094349406217372375986" />
<inertia ixx="6.5860738722373559062e-09" ixy="3.2790901544841979461e-10"  ixz="2.2678298720963275045e-26" iyy="2.2258360502709581268e-09" iyz="-2.1711588075651719382e-25" izz="7.3219808210304026692e-09" />
</inertial>
</link>

<link name="idx-f2-lg_v3_3">
<visual>
<origin xyz="0.00022233297791745751382 -0.0023719290216695364422 6.9322960369946895476e-06" rpy="5.4129569408464892274e-17 9.0292829778344770436e-17 -1.0572593838212323014" />
<geometry>
<mesh filename="./index_2.stl"/>
</geometry>
<material name="index_2_material">
<color rgba="0.98039215686274505668 0.71372549019607844922 0.0039215686274509803377 1.0"/>
</material>
</visual>
<collision>
<origin xyz="0.00022233297791745751382 -0.0023719290216695364422 6.9322960369946895476e-06" rpy="5.4129569408464892274e-17 9.0292829778344770436e-17 -1.0572593838212323014" />
<geometry>
<mesh filename="./index_2.stl"/>
</geometry>
</collision>
<inertial>
<origin xyz="-0.0010461048173382512909 -0.0044321257399922908346 6.5976409530709143983e-06" rpy="0 0 0"/>
<mass value="0.00052398424978570613299" />
<inertia ixx="4.2915366528124720024e-09" ixy="5.8217531578865125336e-11"  ixz="2.9039203123801108011e-13" iyy="6.2215271969257738001e-10" iyz="3.5195995450780240409e-13" izz="4.3113562724289079415e-09" />
</inertial>
</link>

<joint name="ring_joint" type="revolute">
<origin xyz="-0.0015405389275644368677 0.0086198297672773552258 -8.6736173798840354721e-19" rpy="-1.0645765700679691443e-14 -4.5492251087631363691e-15 -2.6429263663145454721" />
<parent link="idx-f1_v3_3" />
<child link="idx-f2-lg_v3_3" />
<axis xyz="0 0 1"/>
<limit effort="1" velocity="20" lower="0.0" upper="2.0943951023931952626"/>
<joint_properties friction="0.0"/>
</joint>

<joint name="palm_ring" type="revolute">
<origin xyz="-0.0060869529459405017843 -0.0039160049841819597263 -0.01189778326773815488" rpy="1.4822410852929528424 -2.0940066999008896269e-05 1.5707981860101365434" />
<parent link="fb_palm_ref_mir_v5" />
<child link="idx-f1_v3_3" />
<axis xyz="0 0 1"/>
<limit effort="1" velocity="20" lower="0" upper="1.570796326794896558"/>
<joint_properties friction="0.0"/>
</joint>

<link name="idx-f1_v3_4">
<visual>
<origin xyz="1.4699462580551082846e-05 0.00097723995259920565237 -3.4694469519536141888e-18" rpy="3.6709854463767563652e-18 -6.2219440531689962972e-17 1.5458638384718461634" />
<geometry>
<mesh filename="./index_1.stl"/>
</geometry>
<material name="index_1_material">
<color rgba="0.2313725490196078538 0.38039215686274507888 0.7058823529411765163 1.0"/>
</material>
</visual>
<collision>
<origin xyz="1.4699462580551082846e-05 0.00097723995259920565237 -3.4694469519536141888e-18" rpy="3.6709854463767563652e-18 -6.2219440531689962972e-17 1.5458638384718461634" />
<geometry>
<mesh filename="./index_1.stl"/>
</geometry>
</collision>
<inertial>
<origin xyz="3.2112843083723419438e-05 0.0044842994521085595416 -4.7737174040300236342e-12" rpy="0 0 0"/>
<mass value="0.00094349406217372375986" />
<inertia ixx="6.5860738722373559062e-09" ixy="3.2790901544841979461e-10"  ixz="2.068500194788456052e-26" iyy="2.2258360502709581268e-09" iyz="-2.8897771730561092328e-25" izz="7.3219808210304026692e-09" />
</inertial>
</link>

<link name="idx-f2-lg_v3_4">
<visual>
<origin xyz="0.00022233297791745838118 -0.0023719290216695360085 6.9322960369946895476e-06" rpy="6.0331530974568247685e-17 8.0286827294417669552e-17 -1.0572593838212323014" />
<geometry>
<mesh filename="./index_2.stl"/>
</geometry>
<material name="index_2_material">
<color rgba="0.98039215686274505668 0.71372549019607844922 0.0039215686274509803377 1.0"/>
</material>
</visual>
<collision>
<origin xyz="0.00022233297791745838118 -0.0023719290216695360085 6.9322960369946895476e-06" rpy="6.0331530974568247685e-17 8.0286827294417669552e-17 -1.0572593838212323014" />
<geometry>
<mesh filename="./index_2.stl"/>
</geometry>
</collision>
<inertial>
<origin xyz="-0.0010461048173382504235 -0.0044321257399922908346 6.5976409530709127042e-06" rpy="0 0 0"/>
<mass value="0.00052398424978570613299" />
<inertia ixx="4.2915366528124711752e-09" ixy="5.8217531578865138261e-11"  ixz="2.9039203123796867095e-13" iyy="6.2215271969257758681e-10" iyz="3.5195995450774207201e-13" izz="4.3113562724289079415e-09" />
</inertial>
</link>

<joint name="pinky_joint" type="revolute">
<origin xyz="-0.0015405389275644368677 0.0086198297672773552258 -1.7347234759768070944e-18" rpy="-1.0612796375347564885e-14 -4.1546907435576699275e-15 -2.6429263663145454721" />
<parent link="idx-f1_v3_4" />
<child link="idx-f2-lg_v3_4" />
<axis xyz="0 0 1"/>
<limit effort="1" velocity="20" lower="0.0" upper="2.0943951023931952626"/>
<joint_properties friction="0.0"/>
</joint>

<joint name="palm_pinky" type="revolute">
<origin xyz="-0.0094418163867134880657 -0.0047880035395979530025 -0.012195671455579346759" rpy="1.4822410852929528424 -2.0940066999005426822e-05 1.5707981860101365434" />
<parent link="fb_palm_ref_mir_v5" />
<child link="idx-f1_v3_4" />
<axis xyz="0 0 1"/>
<limit effort="1" velocity="20" lower="0" upper="1.570796326794896558"/>
<joint_properties friction="0.0"/>
</joint>

<link name="thumb-f1-mir_v3">
<visual>
<origin xyz="0.00017557979167350055288 0.0010577602612661905768 7.465894274546330811e-05" rpy="-3.1404292829428253064 -4.0581339344037132962e-17 0.69123283091690213009" />
<geometry>
<mesh filename="./thumb_1.stl"/>
</geometry>
<material name="thumb_1_material">
<color rgba="0.91764705882352937127 0.91764705882352937127 0.91764705882352937127 1.0"/>
</material>
</visual>
<collision>
<origin xyz="0.00017557979167350055288 0.0010577602612661905768 7.465894274546330811e-05" rpy="-3.1404292829428253064 -4.0581339344037132962e-17 0.69123283091690213009" />
<geometry>
<mesh filename="./thumb_1.stl"/>
</geometry>
</collision>
<inertial>
<origin xyz="0.0020014421990982096851 0.0031202717603482843164 -0.0010150934047534732572" rpy="0 0 0"/>
<mass value="0.00054462429541117063185" />
<inertia ixx="2.1109039290687420253e-09" ixy="-7.9817865869071428504e-10"  ixz="5.2943649390968101632e-10" iyy="1.9864762678676289657e-09" iyz="5.495094795738628708e-10" izz="2.3993427554798496221e-09" />
</inertial>
</link>

<link name="thumb-f2-right_v3">
<visual>
<origin xyz="0.0010313505443626178049 0.0024507775814466004061 -0.00078947225603720472265" rpy="3.6391441414432697617e-17 -1.547525477140208885e-17 -3.5654402414011603593e-17" />
<geometry>
<mesh filename="./thumb_2.stl"/>
</geometry>
<material name="thumb_2_material">
<color rgba="0.64705882352941179736 0.64705882352941179736 0.64705882352941179736 1.0"/>
</material>
</visual>
<collision>
<origin xyz="0.0010313505443626178049 0.0024507775814466004061 -0.00078947225603720472265" rpy="3.6391441414432697617e-17 -1.547525477140208885e-17 -3.5654402414011603593e-17" />
<geometry>
<mesh filename="./thumb_2.stl"/>
</geometry>
</collision>
<inertial>
<origin xyz="0.0066383788263536750579 0.0035590142615154556592 -7.5213638658577276243e-05" rpy="0 0 0"/>
<mass value="0.0027039006703750588165" />
<inertia ixx="1.7318697430115383524e-08" ixy="-1.3057533352685778855e-08"  ixz="7.0633170587282531833e-11" iyy="3.8957351364547130482e-08" iyz="1.5992304266435327577e-11" izz="4.6668567306636538128e-08" />
</inertial>
</link>

<joint name="thumb_joint" type="revolute">
<origin xyz="0.0041333900470498265156 0.0056421827988947133303 -0.0025961400013548227572" rpy="-2.7683448409419399994 1.1780681076743528823 2.8389624729172124873" />
<parent link="thumb-f1-mir_v3" />
<child link="thumb-f2-right_v3" />
<axis xyz="0 0 1"/>
<limit effort="1" velocity="20" lower="-1.0471975511965976313" upper="1.0471975511965976313"/>
<joint_properties friction="0.0"/>
</joint>

<joint name="palm_thumb" type="revolute">
<origin xyz="0.00024641359117504046689 -0.0089114531485886168405 -0.021731039236487736249" rpy="-2.903561262052796188 -0.03499041734889562355 0.55828575372703770352" />
<parent link="fb_palm_ref_mir_v5" />
<child link="thumb-f1-mir_v3" />
<axis xyz="0 0 1"/>
<limit effort="1" velocity="20" lower="0" upper="1.570796326794896558"/>
<joint_properties friction="0.0"/>
</joint>


</robot>
